<?xml version="1.0" ?>
<robot name="spider" xmlns:xacro="http://www.ros.org/wiki/xacro">

<xacro:include filename="$(find spider_description)/urdf/materials.xacro" />
<xacro:include filename="$(find spider_description)/urdf/spider.trans" />
<xacro:include filename="$(find spider_description)/urdf/spider.gazebo" />
<link name="base_link">
  <inertial>
    <origin xyz="-0.0051807055685298845 0.0016789525525093716 0.04999999522434671" rpy="0 0 0"/>
    <mass value="263.0006663023306"/>
    <inertia ixx="4.566198" iyy="12.702097" izz="16.830003" ixy="0.152261" iyz="-0.0" ixz="0.0"/>
  </inertial>
  <visual>
    <origin xyz="0 0 0" rpy="0 0 0"/>
    <geometry>
      <mesh filename="package://spider_description/meshes/base_link.stl" scale="0.001 0.001 0.001"/>
    </geometry>
    <material name="silver"/>
  </visual>
  <collision>
    <origin xyz="0 0 0" rpy="0 0 0"/>
    <geometry>
      <mesh filename="package://spider_description/meshes/base_link.stl" scale="0.001 0.001 0.001"/>
    </geometry>
  </collision>
</link>

<link name="Plink_board_1">
  <inertial>
    <origin xyz="0.019878880406234756 0.010141771791210993 0.0" rpy="0 0 0"/>
    <mass value="0.14930413438956674"/>
    <inertia ixx="4e-05" iyy="7.5e-05" izz="7.4e-05" ixy="-1.9e-05" iyz="0.0" ixz="0.0"/>
  </inertial>
  <visual>
    <origin xyz="-0.45001 -0.1 -0.05" rpy="0 0 0"/>
    <geometry>
      <mesh filename="package://spider_description/meshes/Plink_board_1.stl" scale="0.001 0.001 0.001"/>
    </geometry>
    <material name="silver"/>
  </visual>
  <collision>
    <origin xyz="-0.45001 -0.1 -0.05" rpy="0 0 0"/>
    <geometry>
      <mesh filename="package://spider_description/meshes/Plink_board_1.stl" scale="0.001 0.001 0.001"/>
    </geometry>
  </collision>
</link>

<link name="Plink_board_2">
  <inertial>
    <origin xyz="0.019878880406234756 0.010141771791210952 -4.85722573273506e-17" rpy="0 0 0"/>
    <mass value="0.14930413438956674"/>
    <inertia ixx="4e-05" iyy="7.5e-05" izz="7.4e-05" ixy="-1.9e-05" iyz="-0.0" ixz="-0.0"/>
  </inertial>
  <visual>
    <origin xyz="-0.25001 -0.25 -0.05" rpy="0 0 0"/>
    <geometry>
      <mesh filename="package://spider_description/meshes/Plink_board_2.stl" scale="0.001 0.001 0.001"/>
    </geometry>
    <material name="silver"/>
  </visual>
  <collision>
    <origin xyz="-0.25001 -0.25 -0.05" rpy="0 0 0"/>
    <geometry>
      <mesh filename="package://spider_description/meshes/Plink_board_2.stl" scale="0.001 0.001 0.001"/>
    </geometry>
  </collision>
</link>

<link name="Nlink_board_1">
  <inertial>
    <origin xyz="-0.019878880691994172 0.010141771942031585 -1.3877787807814457e-17" rpy="0 0 0"/>
    <mass value="0.14930413883458316"/>
    <inertia ixx="4e-05" iyy="7.5e-05" izz="7.4e-05" ixy="1.9e-05" iyz="-0.0" ixz="0.0"/>
  </inertial>
  <visual>
    <origin xyz="0.25001 -0.25 -0.05" rpy="0 0 0"/>
    <geometry>
      <mesh filename="package://spider_description/meshes/Nlink_board_1.stl" scale="0.001 0.001 0.001"/>
    </geometry>
    <material name="silver"/>
  </visual>
  <collision>
    <origin xyz="0.25001 -0.25 -0.05" rpy="0 0 0"/>
    <geometry>
      <mesh filename="package://spider_description/meshes/Nlink_board_1.stl" scale="0.001 0.001 0.001"/>
    </geometry>
  </collision>
</link>

<link name="Nlink_board_2">
  <inertial>
    <origin xyz="-0.01987888069199395 0.010141771942031613 1.3877787807814457e-17" rpy="0 0 0"/>
    <mass value="0.14930413883458316"/>
    <inertia ixx="4e-05" iyy="7.5e-05" izz="7.4e-05" ixy="1.9e-05" iyz="0.0" ixz="0.0"/>
  </inertial>
  <visual>
    <origin xyz="0.45001 -0.125 -0.05" rpy="0 0 0"/>
    <geometry>
      <mesh filename="package://spider_description/meshes/Nlink_board_2.stl" scale="0.001 0.001 0.001"/>
    </geometry>
    <material name="silver"/>
  </visual>
  <collision>
    <origin xyz="0.45001 -0.125 -0.05" rpy="0 0 0"/>
    <geometry>
      <mesh filename="package://spider_description/meshes/Nlink_board_2.stl" scale="0.001 0.001 0.001"/>
    </geometry>
  </collision>
</link>

<link name="Nlink_board_3">
  <inertial>
    <origin xyz="0.019878880691994005 -0.010141771942031613 0.0" rpy="0 0 0"/>
    <mass value="0.14930413883458316"/>
    <inertia ixx="4e-05" iyy="7.5e-05" izz="7.4e-05" ixy="1.9e-05" iyz="0.0" ixz="-0.0"/>
  </inertial>
  <visual>
    <origin xyz="-0.45001 0.1 -0.045" rpy="0 0 0"/>
    <geometry>
      <mesh filename="package://spider_description/meshes/Nlink_board_3.stl" scale="0.001 0.001 0.001"/>
    </geometry>
    <material name="silver"/>
  </visual>
  <collision>
    <origin xyz="-0.45001 0.1 -0.045" rpy="0 0 0"/>
    <geometry>
      <mesh filename="package://spider_description/meshes/Nlink_board_3.stl" scale="0.001 0.001 0.001"/>
    </geometry>
  </collision>
</link>

<link name="Nlink_board_4">
  <inertial>
    <origin xyz="0.019878880691994172 -0.01014177194203153 -1.3877787807814457e-17" rpy="0 0 0"/>
    <mass value="0.14930413883458316"/>
    <inertia ixx="4e-05" iyy="7.5e-05" izz="7.4e-05" ixy="1.9e-05" iyz="0.0" ixz="-0.0"/>
  </inertial>
  <visual>
    <origin xyz="-0.25001 0.25 -0.05" rpy="0 0 0"/>
    <geometry>
      <mesh filename="package://spider_description/meshes/Nlink_board_4.stl" scale="0.001 0.001 0.001"/>
    </geometry>
    <material name="silver"/>
  </visual>
  <collision>
    <origin xyz="-0.25001 0.25 -0.05" rpy="0 0 0"/>
    <geometry>
      <mesh filename="package://spider_description/meshes/Nlink_board_4.stl" scale="0.001 0.001 0.001"/>
    </geometry>
  </collision>
</link>

<link name="Plink_board_3">
  <inertial>
    <origin xyz="-0.019878880406234756 -0.010141771791210952 -4.85722573273506e-17" rpy="0 0 0"/>
    <mass value="0.14930413438956674"/>
    <inertia ixx="4e-05" iyy="7.5e-05" izz="7.4e-05" ixy="-1.9e-05" iyz="0.0" ixz="0.0"/>
  </inertial>
  <visual>
    <origin xyz="0.25001 0.25 -0.05" rpy="0 0 0"/>
    <geometry>
      <mesh filename="package://spider_description/meshes/Plink_board_3.stl" scale="0.001 0.001 0.001"/>
    </geometry>
    <material name="silver"/>
  </visual>
  <collision>
    <origin xyz="0.25001 0.25 -0.05" rpy="0 0 0"/>
    <geometry>
      <mesh filename="package://spider_description/meshes/Plink_board_3.stl" scale="0.001 0.001 0.001"/>
    </geometry>
  </collision>
</link>

<link name="Plink_board_4">
  <inertial>
    <origin xyz="-0.019878880406234534 -0.01014177179121098 -6.938893903907228e-18" rpy="0 0 0"/>
    <mass value="0.14930413438956674"/>
    <inertia ixx="4e-05" iyy="7.5e-05" izz="7.4e-05" ixy="-1.9e-05" iyz="0.0" ixz="0.0"/>
  </inertial>
  <visual>
    <origin xyz="0.45001 0.1 -0.045" rpy="0 0 0"/>
    <geometry>
      <mesh filename="package://spider_description/meshes/Plink_board_4.stl" scale="0.001 0.001 0.001"/>
    </geometry>
    <material name="silver"/>
  </visual>
  <collision>
    <origin xyz="0.45001 0.1 -0.045" rpy="0 0 0"/>
    <geometry>
      <mesh filename="package://spider_description/meshes/Plink_board_4.stl" scale="0.001 0.001 0.001"/>
    </geometry>
  </collision>
</link>

<link name="Pcalf_1">
  <inertial>
    <origin xyz="-5.55138551794343e-09 0.002499549328502923 -0.1307761990337935" rpy="0 0 0"/>
    <mass value="0.8567715125260319"/>
    <inertia ixx="0.003554" iyy="0.003641" izz="0.00064" ixy="0.0" iyz="0.0" ixz="-0.0"/>
  </inertial>
  <visual>
    <origin xyz="-0.48001 -0.12001 -0.05" rpy="0 0 0"/>
    <geometry>
      <mesh filename="package://spider_description/meshes/Pcalf_1.stl" scale="0.001 0.001 0.001"/>
    </geometry>
    <material name="silver"/>
  </visual>
  <collision>
    <origin xyz="-0.48001 -0.12001 -0.05" rpy="0 0 0"/>
    <geometry>
      <mesh filename="package://spider_description/meshes/Pcalf_1.stl" scale="0.001 0.001 0.001"/>
    </geometry>
  </collision>
</link>

<link name="Pcalf_2">
  <inertial>
    <origin xyz="-5.55138551794343e-09 0.0024995493285029924 -0.1307761990337935" rpy="0 0 0"/>
    <mass value="0.8567715125260319"/>
    <inertia ixx="0.003554" iyy="0.003641" izz="0.00064" ixy="0.0" iyz="0.0" ixz="-0.0"/>
  </inertial>
  <visual>
    <origin xyz="-0.28001 -0.27001 -0.05" rpy="0 0 0"/>
    <geometry>
      <mesh filename="package://spider_description/meshes/Pcalf_2.stl" scale="0.001 0.001 0.001"/>
    </geometry>
    <material name="silver"/>
  </visual>
  <collision>
    <origin xyz="-0.28001 -0.27001 -0.05" rpy="0 0 0"/>
    <geometry>
      <mesh filename="package://spider_description/meshes/Pcalf_2.stl" scale="0.001 0.001 0.001"/>
    </geometry>
  </collision>
</link>

<link name="Pcalf_3">
  <inertial>
    <origin xyz="3.83634596312632e-09 0.002499549626526154 -0.1307761990337935" rpy="0 0 0"/>
    <mass value="0.8567715125260319"/>
    <inertia ixx="0.003554" iyy="0.003641" izz="0.00064" ixy="0.0" iyz="0.0" ixz="-0.0"/>
  </inertial>
  <visual>
    <origin xyz="0.28001 -0.27001 -0.05" rpy="0 0 0"/>
    <geometry>
      <mesh filename="package://spider_description/meshes/Pcalf_3.stl" scale="0.001 0.001 0.001"/>
    </geometry>
    <material name="silver"/>
  </visual>
  <collision>
    <origin xyz="0.28001 -0.27001 -0.05" rpy="0 0 0"/>
    <geometry>
      <mesh filename="package://spider_description/meshes/Pcalf_3.stl" scale="0.001 0.001 0.001"/>
    </geometry>
  </collision>
</link>

<link name="Pcalf_4">
  <inertial>
    <origin xyz="3.836345241481354e-09 0.0024995496265261263 -0.1307761990337935" rpy="0 0 0"/>
    <mass value="0.8567715125260319"/>
    <inertia ixx="0.003554" iyy="0.003641" izz="0.00064" ixy="0.0" iyz="0.0" ixz="-0.0"/>
  </inertial>
  <visual>
    <origin xyz="0.48001 -0.14501 -0.05" rpy="0 0 0"/>
    <geometry>
      <mesh filename="package://spider_description/meshes/Pcalf_4.stl" scale="0.001 0.001 0.001"/>
    </geometry>
    <material name="silver"/>
  </visual>
  <collision>
    <origin xyz="0.48001 -0.14501 -0.05" rpy="0 0 0"/>
    <geometry>
      <mesh filename="package://spider_description/meshes/Pcalf_4.stl" scale="0.001 0.001 0.001"/>
    </geometry>
  </collision>
</link>

<link name="Ncalf_1">
  <inertial>
    <origin xyz="-3.836346018637471e-09 -0.0024995496265262374 -0.1307761990337935" rpy="0 0 0"/>
    <mass value="0.8567715125260319"/>
    <inertia ixx="0.003554" iyy="0.003641" izz="0.00064" ixy="0.0" iyz="-0.0" ixz="0.0"/>
  </inertial>
  <visual>
    <origin xyz="-0.48001 0.12001 -0.045" rpy="0 0 0"/>
    <geometry>
      <mesh filename="package://spider_description/meshes/Ncalf_1.stl" scale="0.001 0.001 0.001"/>
    </geometry>
    <material name="silver"/>
  </visual>
  <collision>
    <origin xyz="-0.48001 0.12001 -0.045" rpy="0 0 0"/>
    <geometry>
      <mesh filename="package://spider_description/meshes/Ncalf_1.stl" scale="0.001 0.001 0.001"/>
    </geometry>
  </collision>
</link>

<link name="Ncalf_4">
  <inertial>
    <origin xyz="-3.83634596312632e-09 -0.0024995496265262096 -0.1307761990337936" rpy="0 0 0"/>
    <mass value="0.8567715125260319"/>
    <inertia ixx="0.003554" iyy="0.003641" izz="0.00064" ixy="0.0" iyz="-0.0" ixz="0.0"/>
  </inertial>
  <visual>
    <origin xyz="-0.28001 0.27001 -0.05" rpy="0 0 0"/>
    <geometry>
      <mesh filename="package://spider_description/meshes/Ncalf_4.stl" scale="0.001 0.001 0.001"/>
    </geometry>
    <material name="silver"/>
  </visual>
  <collision>
    <origin xyz="-0.28001 0.27001 -0.05" rpy="0 0 0"/>
    <geometry>
      <mesh filename="package://spider_description/meshes/Ncalf_4.stl" scale="0.001 0.001 0.001"/>
    </geometry>
  </collision>
</link>

<link name="Ncalf_5">
  <inertial>
    <origin xyz="5.55138551794343e-09 -0.002499549328503048 -0.1307761990337935" rpy="0 0 0"/>
    <mass value="0.8567715125260319"/>
    <inertia ixx="0.003554" iyy="0.003641" izz="0.00064" ixy="0.0" iyz="-0.0" ixz="0.0"/>
  </inertial>
  <visual>
    <origin xyz="0.28001 0.27001 -0.05" rpy="0 0 0"/>
    <geometry>
      <mesh filename="package://spider_description/meshes/Ncalf_5.stl" scale="0.001 0.001 0.001"/>
    </geometry>
    <material name="silver"/>
  </visual>
  <collision>
    <origin xyz="0.28001 0.27001 -0.05" rpy="0 0 0"/>
    <geometry>
      <mesh filename="package://spider_description/meshes/Ncalf_5.stl" scale="0.001 0.001 0.001"/>
    </geometry>
  </collision>
</link>

<link name="Ncalf_6">
  <inertial>
    <origin xyz="5.551385628965733e-09 -0.002499549328503034 -0.1307761990337935" rpy="0 0 0"/>
    <mass value="0.8567715125260319"/>
    <inertia ixx="0.003554" iyy="0.003641" izz="0.00064" ixy="0.0" iyz="-0.0" ixz="0.0"/>
  </inertial>
  <visual>
    <origin xyz="0.48001 0.12001 -0.045" rpy="0 0 0"/>
    <geometry>
      <mesh filename="package://spider_description/meshes/Ncalf_6.stl" scale="0.001 0.001 0.001"/>
    </geometry>
    <material name="silver"/>
  </visual>
  <collision>
    <origin xyz="0.48001 0.12001 -0.045" rpy="0 0 0"/>
    <geometry>
      <mesh filename="package://spider_description/meshes/Ncalf_6.stl" scale="0.001 0.001 0.001"/>
    </geometry>
  </collision>
</link>

<joint name="Revolute 1" type="continuous">
  <origin xyz="0.45001 0.1 0.05" rpy="0 0 0"/>
  <parent link="base_link"/>
  <child link="Plink_board_1"/>
  <axis xyz="1.0 0.0 0.0"/>
</joint>

<joint name="Revolute 2" type="continuous">
  <origin xyz="0.25001 0.25 0.05" rpy="0 0 0"/>
  <parent link="base_link"/>
  <child link="Plink_board_2"/>
  <axis xyz="1.0 0.0 0.0"/>
</joint>

<joint name="Revolute 3" type="continuous">
  <origin xyz="-0.25001 0.25 0.05" rpy="0 0 0"/>
  <parent link="base_link"/>
  <child link="Nlink_board_1"/>
  <axis xyz="-1.0 0.0 0.0"/>
</joint>

<joint name="Revolute 4" type="continuous">
  <origin xyz="-0.45001 0.125 0.05" rpy="0 0 0"/>
  <parent link="base_link"/>
  <child link="Nlink_board_2"/>
  <axis xyz="-1.0 0.0 0.0"/>
</joint>

<joint name="Revolute 5" type="continuous">
  <origin xyz="0.45001 -0.1 0.045" rpy="0 0 0"/>
  <parent link="base_link"/>
  <child link="Nlink_board_3"/>
  <axis xyz="1.0 0.0 0.0"/>
</joint>

<joint name="Revolute 6" type="continuous">
  <origin xyz="0.25001 -0.25 0.05" rpy="0 0 0"/>
  <parent link="base_link"/>
  <child link="Nlink_board_4"/>
  <axis xyz="1.0 0.0 0.0"/>
</joint>

<joint name="Revolute 7" type="continuous">
  <origin xyz="-0.25001 -0.25 0.05" rpy="0 0 0"/>
  <parent link="base_link"/>
  <child link="Plink_board_3"/>
  <axis xyz="-1.0 0.0 0.0"/>
</joint>

<joint name="Revolute 8" type="continuous">
  <origin xyz="-0.45001 -0.1 0.045" rpy="0 0 0"/>
  <parent link="base_link"/>
  <child link="Plink_board_4"/>
  <axis xyz="-1.0 0.0 0.0"/>
</joint>

<joint name="Revolute 9" type="continuous">
  <origin xyz="0.03 0.02001 0.0" rpy="0 0 0"/>
  <parent link="Plink_board_1"/>
  <child link="Pcalf_1"/>
  <axis xyz="0.0 1.0 0.0"/>
</joint>

<joint name="Revolute 10" type="continuous">
  <origin xyz="0.03 0.02001 0.0" rpy="0 0 0"/>
  <parent link="Plink_board_2"/>
  <child link="Pcalf_2"/>
  <axis xyz="0.0 1.0 0.0"/>
</joint>

<joint name="Revolute 11" type="continuous">
  <origin xyz="-0.03 0.02001 0.0" rpy="0 0 0"/>
  <parent link="Nlink_board_1"/>
  <child link="Pcalf_3"/>
  <axis xyz="0.0 1.0 0.0"/>
</joint>

<joint name="Revolute 12" type="continuous">
  <origin xyz="-0.03 0.02001 0.0" rpy="0 0 0"/>
  <parent link="Nlink_board_2"/>
  <child link="Pcalf_4"/>
  <axis xyz="0.0 1.0 0.0"/>
</joint>

<joint name="Revolute 13" type="continuous">
  <origin xyz="0.03 -0.02001 0.0" rpy="0 0 0"/>
  <parent link="Nlink_board_3"/>
  <child link="Ncalf_1"/>
  <axis xyz="0.0 -1.0 0.0"/>
</joint>

<joint name="Revolute 14" type="continuous">
  <origin xyz="0.03 -0.02001 0.0" rpy="0 0 0"/>
  <parent link="Nlink_board_4"/>
  <child link="Ncalf_4"/>
  <axis xyz="0.0 -1.0 0.0"/>
</joint>

<joint name="Revolute 15" type="continuous">
  <origin xyz="-0.03 -0.02001 0.0" rpy="0 0 0"/>
  <parent link="Plink_board_3"/>
  <child link="Ncalf_5"/>
  <axis xyz="0.0 -1.0 0.0"/>
</joint>

<joint name="Revolute 16" type="continuous">
  <origin xyz="-0.03 -0.02001 0.0" rpy="0 0 0"/>
  <parent link="Plink_board_4"/>
  <child link="Ncalf_6"/>
  <axis xyz="0.0 -1.0 0.0"/>
</joint>

</robot>
